Workbook

Sheet Egg Rolls
B1: Size | C1: Weight | E1: Size | F1: Weight
A2: *wholesale only | B2: 1.5' x 5' | C2: 2oz/roll | E2: 1' x 4' | F2: 1.5oz/roll
D3: Wholesale Price | H3: Wholesale Price
A4: Large Vegetable* | B4: 1.5' x 5' | C4: $.76cent | E4: Small Vegetable | F4: 1' x 4' | G4: $.72cent
A5: Carrot | B5: 23lb | C5: 20 | E5: Carrot | F5: 23lb | G5: 20
A6: Taro | B6: 35lb | C6: 50 | E6: Taro | F6: 35lb | G6: 50
A7: cabbage | B7: 25lb | C7: 25 | E7: cabbage | F7: 25lb | G7: 25
A8: onion | B8: 23lb | C8: 20 | E8: onion | F8: 23lb | G8: 20 | N8: 101 | O8: Carrots
A9: salt | B9: .5lb | C9: 0.5 | E9: salt | F9: .5lb | G9: 0.5 | J9: Salt | K9: 10lbs | L9: 10 | N9: 102 | O9: Taro
A10: Sugar | B10: .5lb | C10: 0.5 | E10: Sugar | F10: .5lb | G10: 0.5 | J10: Pepper | K10: 5lb | L10: 35 | N10: 103 | O10: Cabbage
A11: Mushroom seasoning | B11: .5lb | C11: 2.75 | E11: Mushroom seasoning | F11: .5lbs | G11: =5.5/2 -> 2.75 | J11: Sugar | K11: 25lbs | L11: 25 | N11: 104 | O11: onions
A12: Wrapper | B12: 1200 sheet | C12: 60 | E12: Wrapper | F12: 1500 | G12: 75 | J12: CB | K12: 5lb | L12: 20 | N12: 105 | O12: salt
A13: vermicelli | B13: 8 | C13: 10 | E13: vermicelli | F13: 8 | G13: 10 | J13: Mushroom Powder | K13: 1lb | L13: 5.5 | N13: 106 | O13: Pepper
A14: Total | C14: =SUM(C5:C13) -> 188.75 | E14: Total | G14: =SUM(G5:G13) -> 203.75 | N14: 107 | O14: sugar
A15: Cost/roll | C15: =189/1200 -> 0.1575 | E15: Cost/roll | G15: =204/1500 -> 0.136 | N15: 108 | O15: CB
A16: Actual cost | C16: =sum(0.15+0.23) -> 0.38 | E16: Actual Cost | G16: =sum(0.14+0.23) -> 0.37 | N16: 109 | O16: Mushroom Powder
K17: best practice = keep all cost current | N17: 110 | O17: Wrappers
A18: Taro | B18: 1'x 4' | C18: $.72cent | K18: material, labor and overhead | N18: 111 | O18: Vermicelli
A19: Onion | B19: 23lbs | C19: 20 | K19: Keep track of production
A20: Vermicelli | B20: 8 | C20: 10
A21: Carrot | B21: 23lb | C21: 20 | K21: Working with suppliers
A22: Taro | B22: 35lb | C22: 50 | K22: -get credit terms
A23: Mushroom bouillon | B23: 0.5lb | C23: 2.75
A24: salt | B24: .5lb | C24: 0.5
A25: Sugar | B25: .5lb | C25: 0.5
A26: wrapper | B26: 1500 | C26: 75
A27: Total | C27: =sum(C19:C26) -> 178.75
A28: Cost/roll | C28: =179/1500 -> 0.11933333
A31: Large Chicken* | B31: 1.5' x 5' | C31: .76cent | E31: Small Chicken | F31: 1' x 4' | G31: .74cent | H31: cooked $1
A32: Minced Chicken | B32: 35lb | C32: 70 | E32: Minced Chicken | F32: 40lb | G32: 80
A33: Onion | B33: 14lb | C33: 10 | E33: Onion | F33: 14lb | G33: 10
A34: Vermicelli | B34: 8 | C34: 10 | E34: Vermicelli | F34: 8 | G34: 10
A35: Carrot | B35: 14lb | C35: 10 | E35: Carrot | F35: 14lb | G35: 10
A36: Taro | B36: 20lb | C36: 30 | E36: Taro | F36: 20lb | G36: 30
A37: cabbage | B37: 20lb | C37: 15 | E37: black pepper | F37: .5lb | G37: 3.5
A38: black pepper | B38: .5lb | C38: 3.5 | E38: Chicken flavor bouillon | F38: .5lb | G38: 2
A39: Chicken flavor bouillon | B39: .5lb | C39: 2 | E39: salt | F39: .5lb | G39: 0.5
A40: salt | B40: .5lb | C40: 0.5 | E40: Sugar | F40: .5lb | G40: 0.5
A41: Sugar | B41: .5lb | C41: 0.5 | E41: wrapper | F41: 1500 sheet | G41: 75
A42: wrapper | B42: 1200 sheet | C42: 60 | E42: Total | G42: =SUM(G32:G41) -> 221.5
...

Sheet Sheet4
A1: prices | E1: per roll | F1: profit per roll | G1: margin
A2: cooked pork and shrimp | B2: 1.2 | C2: 1.25
A3: cooked pork | B3: 1.1 | C3: 1.2
A4: cooked shrimp | B4: 1.25 | C4: 1.3
A5: cooked chicken | B5: 1.1 | C5: 1.2
A6: cooked taro | B6: 1 | C6: 1.15
A7: cooked vegetable | B7: 1 | C7: 1.15
A10: frozen pork and shrimp | B10: $44 for 50pcs | C10: 46 | D10: 52 | E10: =C10/50 -> 0.92 | F10: =E10-'Egg Rolls'!E22 -> 0.92 | G10: =F10/E10 -> 1
A11: frozen pork | B11: $39 for 50pcs | C11: 44 | D11: 48 | E11: =C11/50 -> 0.88 | F11: =E11-'Egg Rolls'!G58 -> 0.732 | G11: =F11/E11 -> 0.83181818
A12: frozen shrimp | B12: $46 for 50pcs | C12: 49 | D12: 49 | E12: =C12/50 -> 0.98 | F12: =E12-'Egg Rolls'!C74 -> 0.86 | G12: =F12/E12 -> 0.87755102
A13: frozen chicken | B13: $40 for 50pcs | C13: 44 | D13: 50 | E13: =C13/50 -> 0.88 | F13: =E13-0.148 -> 0.732 | G13: =F13/E13 -> 0.83181818
A14: frozen taro | B14: $38 for 50pcs | C14: 44 | D14: 46 | E14: =C14/50 -> 0.88 | F14: =E14-'Egg Rolls'!C28 -> 0.76066667 | G14: =F14/E14 -> 0.86439394
A15: frozen vegetable | B15: $38 for 50pcs | C15: 43 | D15: 48 | E15: =C15/50 -> 0.86 | F15: =E15-'Egg Rolls'!G16 -> 0.49 | G15: =F15/E15 -> 0.56976744
A16: frozen wonton | B16: $12 for 30 pc | C16: 14
A17: banh bot loc | B17: $38 per bag | C17: 40

Sheet Overhead Cost
B1: $ spend/unit | D1: Daily | E1: Monthly | F1: Quarterly | G1: Yearly
A2: Uiltilies | D2: 36.67 | E2: 1100
A3: Rent | E3: 3450
A4: Business Insurance | E4: =2200/12 -> 183.33333 | G4: 2200
A5: Car payment | E5: 1100
A6: POS fees | C6: .3% +0.10 fee per transaction | E6: 100.58
A7: Accounting/book keeping fees | E7: =450/3 -> 150 | F7: 450
A8: Phone Bills | E8: 75
A9: Licensing | E9: =105/12 -> 8.75 | G9: 105
E10: =SUM(E2:E9) -> 6167.6633
B13: Quantity/Month | D13: Cost/Month
A14: Miscellaneous
A15: Foil Tray- large | B15: 100 | C15: 36.49*2 | D15: =36.49*2 -> 72.98
A16: Foil Tray- Small | B16: 100 | C16: 25.99 | D16: 25.99
A17: Clear plastic bag | B17: 2000 | C17: 20 | D17: 20
A18: To go plastic bag | B18: 500 | C18: 54.99 | D18: 54.99
A19: Soy Bean oil | B19: 4 per month | C19: 34.99*4 | D19: =34.99*4 -> 139.96
A20: labels | B20: 2000 | C20: 5 | D20: 5
A21: To go box | B21: 200 | C21: 51.99 | D21: 519
A22: Trash Bags | B22: 2 box | C22: 23.99*2 | D22: =23.99*2 -> 47.98
A23: Toilet Paper | B23: 2 | C23: 23.49*2 | D23: =23.49*2 -> 46.98
A24: Paper Towel | B24: 2 | C24: 22.99*2 | D24: =22.99*2 -> 45.98
D25: =SUM(D14:D24) -> 978.86

Sheet Labor
A1: Column 1 | B1: Name | C1: Title | D1: Rate | E1: hours | F1: Daily | G1: Daily + Benefit (additional 25%) | H1: Weekly | I1: Monthly | J1: Insurance
B2: HUA, Phoung | C2: Manager | D2: 8000/monthly | E2: - | F2: 266.67 | G2: =F2*1.25 -> 333.3375 | H2: =8000/4 -> 2000 | I2: 8000
B3: WONG, Rayment | C3: Manager | D3: 8000/monthly | E3: - | F3: 266.67 | G3: =F3*1.25 -> 333.3375 | H3: 2000 | I3: 8000
B4: WONG, Jason | C4: Admin | D4: 19.97 | E4: 130 | F4: =D4*8 -> 159.76 | G4: =F4*1.25 -> 199.7 | H4: =D4*40 -> 798.8 | I4: =D4*E4 -> 2596.1
B5: CHAU, Sat | C5: Food Preperation | D5: 21 | E5: 160 | F5: =D5*8 -> 168 | G5: =F5*1.25 -> 210 | H5: =D5*40 -> 840 | I5: =D5*E5 -> 3360
B6: LIN, Miao | C6: Food Preperation | D6: 19.97 | E6: 130 | F6: =D6*8 -> 159.76 | G6: =F6*1.25 -> 199.7 | H6: =D6*40 -> 798.8 | I6: =D6*E6 -> 2596.1
B7: WONG, Lin | C7: Food Preperation | D7: 19.97 | E7: 130 | F7: =D7*8 -> 159.76 | G7: =F7*1.25 -> 199.7 | H7: =D7*40 -> 798.8 | I7: =D7*E7 -> 2596.1
B8: ZHEN, Mao | C8: Food Preperation | D8: 19.97 | E8: 130 | F8: =D8*8 -> 159.76 | G8: =F8*1.25 -> 199.7 | H8: =D8*40 -> 798.8 | I8: =D8*E8 -> 2596.1
B9: NGUYEN, Ngoc | C9: Food Processing | D9: 21 | E9: 160 | F9: =D9*8 -> 168 | G9: =F9*1.25 -> 210 | H9: =D9*40 -> 840 | I9: =D9*E9 -> 3360
B10: WONG, Kevin | C10: Food Processing | D10: 19.97 | E10: 130 | F10: =D10*8 -> 159.76 | G10: =F10*1.25 -> 199.7 | H10: =D10*40 -> 798.8 | I10: =D10*E10 -> 2596.1
A11: Total | F11: =SUM(F2:F10) -> 1668.14 | G11: =F11*1.25 -> 2085.175 | I11: =SUM(I2:I10) -> 35700.5
B15: Rolls
A16: Monthly ( avg 25 working day) | B16: 200000
A17: Daily Output | B17: 8000
A18: Hourly Output | B18: =8000/8 -> 1000
B20: total daily wages/ total eggroll | F20: assum total hours = 1230 (all employees on payroll)
A22: Insurance Benefit (who gets, how much) | B22: 3550
A23: Overhead | B23: 7155.86
A24: Wages | B24: 35700.5 | F24: 46406.36/1230= 37.7 cost per hour per person (overhead cost + labor cost)
A25: total | B25: =sum(B22,B23,B24) -> 46406.36 | C25: fix and variable overhead
A26: /roll | B26: =B25/B16 -> 0.2320318
B29: =110/1000 -> 0.11 | C29: =100/1000 -> 0.1
